Workbook

Sheet Assumptions
A1: DETAILHAUS — COSTING MODEL ASSUMPTIONS (EM20260613)
A3: Global Inputs
A4: Item | B4: Value | C4: Unit | D4: Notes
A5: USD to KES exchange rate | B5: 135 | C5: KES | D5: Set per current/expected rate
A6: Shipping rate (per CBM) | B6: 61500 | C6: KES | D6: Midpoint of 60,000–63,000 KES/CBM quoted
A7: Estimated shipment volume (CBM) | B7: 1.2 | C7: CBM | D7: Estimate — see Shipping tab for basis
A8: Customs/duty + IDF + clearing agent (% of CIF) | B8: 0.25 | C8: % | D8: Typical KRA duty+VAT+IDF for car care goods — VERIFY with clearing agent
A9: Labour add-on (% of product cost per job) | B9: 0.15 | C9: % | D9: Midpoint of 10-20% range requested
A10: Target markup (on cost incl. labour) | B10: 0.5 | C10: % | D10: Placeholder — adjust as needed
A12: Order Summary (from SRB invoices EM20260613)
A13: Item | B13: USD | C13: KES (landed est.)
A14: Invoice — Chemicals (sub-total) | B14: 3803 | C14: =B14*$B$5 -> 513405
A15: Invoice — Tools & Equipment (sub-total) | B15: 1591.58 | C15: =B15*$B$5 -> 214863.3
A16: Goods sub-total (EXW Guangzhou) | B16: =SUM(B14:B15) -> 5394.58 | C16: =B16*$B$5 -> 728268.3
A17: Shipping cost (CBM × rate) | B17: =(B7*B6)/B5 -> 546.66667 | C17: =B7*B6 -> 73800
A18: CIF value (goods + shipping) | B18: =B16+B17 -> 5941.2467 | C18: =B18*$B$5 -> 802068.3
A19: Estimated duty/VAT/clearing | B19: =B18*B8 -> 1485.3117 | C19: =B19*$B$5 -> 200517.08
A20: TOTAL LANDED COST | B20: =B18+B19 -> 7426.5583 | C20: =B20*$B$5 -> 1002585.4
A21: Landed cost uplift factor (multiplier on EXW price) | B21: =B20/B16 -> 1.3766703
A22: Note: apply the uplift factor to each item's EXW unit price to get its landed unit cost in Nairobi (covers freight, duty, VAT, clearing). Adjust CBM and duty % once you have actuals from the freight forwarder.

Sheet Package Summary
A1: DETAILHAUS — FINAL SERVICE & PRICING SUMMARY (14 Jun 2026)
A2: Final retail prices set via competitor-benchmarked repricing (see Master Pricing & Costing PDF for positioning rationale). Cost/Price/Profit/Margin columns for Core Tiers, Add-ons and Membership link live to the Package Costing tab. PPF and Window Tint costs are landed per-car costs from the dedicated PPF/Tint costing workpapers (Product Costs items incl. S33, C36, S-681, T-651/652, S12, T-77).
A4: CORE DETAILING TIERS
A5: Package / Film | B5: Cost Sedan | C5: Final Price Sedan | D5: Profit Sedan | E5: Margin Sedan | F5: Cost SUV | G5: Final Price SUV | H5: Profit SUV | I5: Margin SUV
A6: Bronze — Express Wash & Shine | B6: ='Package Costing'!G24 -> 700.10528 | C6: ='Package Costing'!G25 -> 5000 | D6: =C6-B6 -> 4299.8947 | E6: =D6/C6 -> 0.85997894 | F6: ='Package Costing'!H24 -> 910.13687 | G6: ='Package Costing'!H25 -> 7000 | H6: =G6-F6 -> 6089.8631 | I6: =H6/G6 -> 0.86998045
A7: Silver — Household Detail | B7: ='Package Costing'!G66 -> 1488.6341 | C7: ='Package Costing'!G67 -> 18000 | D7: =C7-B7 -> 16511.366 | E7: =D7/C7 -> 0.9172981 | F7: ='Package Costing'!H66 -> 1935.2244 | G7: ='Package Costing'!H67 -> 22000 | H7: =G7-F7 -> 20064.776 | I7: =H7/G7 -> 0.91203526
A8: Gold — Complete Detail (100%) | B8: ='Package Costing'!G126 -> 4579.1604 | C8: ='Package Costing'!G127 -> 40000 | D8: =C8-B8 -> 35420.84 | E8: =D8/C8 -> 0.88552099 | F8: ='Package Costing'!H126 -> 5952.9086 | G8: ='Package Costing'!H127 -> 50000 | H8: =G8-F8 -> 44047.091 | I8: =H8/G8 -> 0.88094183
A9: Platinum 10H — 2-3yr Coating | B9: ='Package Costing'!G192 -> 35309.54 | C9: ='Package Costing'!G193 -> 90000 | D9: =C9-B9 -> 54690.46 | E9: =D9/C9 -> 0.60767178 | F9: ='Package Costing'!H192 -> 45902.402 | G9: ='Package Costing'!H193 -> 110000 | H9: =G9-F9 -> 64097.598 | I9: =H9/G9 -> 0.58270543
A10: Platinum 20H — Flagship Coating | B10: ='Package Costing'!G258 -> 72580.757 | C10: ='Package Costing'!G259 -> 150000 | D10: =C10-B10 -> 77419.243 | E10: =D10/C10 -> 0.51612829 | F10: ='Package Costing'!H258 -> 94354.984 | G10: ='Package Costing'!H259 -> 180000 | H10: =G10-F10 -> 85645.016 | I10: =H10/G10 -> 0.47580564
A12: ADD-ON SERVICES
A13: Package / Film | B13: Cost Sedan | C13: Final Price Sedan | D13: Profit Sedan | E13: Margin Sedan | F13: Cost SUV | G13: Final Price SUV | H13: Profit SUV | I13: Margin SUV
A14: Glass Coating (standalone) | B14: ='Package Costing'!G270 -> 3473.6796 | C14: ='Package Costing'!G271 -> 10000 | D14: =C14-B14 -> 6526.3204 | E14: =D14/C14 -> 0.65263204 | F14: ='Package Costing'!H270 -> 4515.7835 | G14: ='Package Costing'!H271 -> 12000 | H14: =G14-F14 -> 7484.2165 | I14: =H14/G14 -> 0.62368471
A15: Paint Correction (3-Step Polish) | B15: ='Package Costing'!G293 -> 749.57543 | C15: ='Package Costing'!G294 -> 22000 | D15: =C15-B15 -> 21250.425 | E15: =D15/C15 -> 0.96592839 | F15: ='Package Costing'!H293 -> 974.44806 | G15: ='Package Costing'!H294 -> 28000 | H15: =G15-F15 -> 27025.552 | I15: =H15/G15 -> 0.96519828
A16: Ceramic Coating 10H (Standalone) | B16: ='Package Costing'!G411 -> 31560.183 | C16: ='Package Costing'!G412 -> 65000 | D16: =C16-B16 -> 33439.817 | E16: =D16/C16 -> 0.51445872 | F16: ='Package Costing'!H411 -> 41028.238 | G16: ='Package Costing'!H412 -> 80000 | H16: =G16-F16 -> 38971.762 | I16: =H16/G16 -> 0.48714702
A17: Ceramic Coating 20H (Standalone Flagship) | B17: ='Package Costing'!G442 -> 68831.4 | C17: ='Package Costing'!G443 -> 110000 | D17: =C17-B17 -> 41168.6 | E17: =D17/C17 -> 0.37426 | F17: ='Package Costing'!H442 -> 89480.82 | G17: ='Package Costing'!H443 -> 135000 | H17: =G17-F17 -> 45519.18 | I17: =H17/G17 -> 0.33717911
A18: New Car Detailing | B18: ='Package Costing'!G346 -> 4467.4685 | C18: ='Package Costing'!G347 -> 45000 | D18: =C18-B18 -> 40532.532 | E18: =D18/C18 -> 0.90072292 | F18: ='Package Costing'!H346 -> 5807.709 | G18: ='Package Costing'!H347 -> 55000 | H18: =G18-F18 -> 49192.291 | I18: =H18/G18 -> 0.89440529
A19: A/C Deep Clean & Decontamination | B19: ='Package Costing'!G455 -> 1737.9654 | C19: ='Package Costing'!G456 -> 3500 | D19: =C19-B19 -> 1762.0346 | E19: =D19/C19 -> 0.50343845 | F19: ='Package Costing'!H455 -> 2259.3551 | G19: ='Package Costing'!H456 -> 4500 | H19: =G19-F19 -> 2240.6449 | I19: =H19/G19 -> 0.4979211
A21: MEMBERSHIP
A22: Package / Film | B22: Cost Sedan | C22: Final Price Sedan | F22: Cost SUV | G22: Final Price SUV
A23: Maintenance Club (per month) | B23: ='Package Costing'!G380 -> 1758.7201 | C23: ='Package Costing'!G381 -> 11700 | D23: =C23-B23 -> 9941.2799 | E23: =D23/C23 -> 0.84968204 | F23: ='Package Costing'!H380 -> 2286.3361 | G23: ='Package Costing'!H381 -> 15100 | H23: =G23-F23 -> 12813.664 | I23: =H23/G23 -> 0.84858701
A24: PPF Maintenance Club (per month) | B24: ='Package Costing'!G532 -> 1477.9882 | C24: ='Package Costing'!G533 -> 11700 | D24: =C24-B24 -> 10222.012 | E24: =D24/C24 -> 0.87367622 | F24: ='Package Costing'!H532 -> 1921.3847 | G24: ='Package Costing'!H533 -> 15100 | H24: =G24-F24 -> 13178.615 | I24: =H24/G24 -> 0.87275598
A26: PAINT PROTECTION FILM (PPF)
A27: Package / Film | B27: Cost Sedan | C27: Final Price Sedan | D27: Profit Sedan | E27: Margin Sedan | F27: Cost SUV | G27: Final Price SUV | H27: Profit SUV | I27: Margin SUV
A28: Partial Front — Xpel Ultimate Plus | B28: 12405 | C28: 52000 | D28: =C28-B28 -> 39595 | E28: =D28/C28 -> 0.76144231 | F28: 12405 | G28: 52000 | H28: =G28-F28 -> 39595 | I28: =H28/G28 -> 0.76144231
A29: Partial Front — 3M Scotchgard (Glossy) | B29: 13447 | C29: 58000 | D29: =C29-B29 -> 44553 | E29: =D29/C29 -> 0.76815517 | F29: 13447 | G29: 58000 | H29: =G29-F29 -> 44553 | I29: =H29/G29 -> 0.76815517
A30: Partial Front — 3M Scotchgard (Matte) | B30: 13933 | C30: 62000 | D30: =C30-B30 -> 48067 | E30: =D30/C30 -> 0.77527419 | F30: 13933 | G30: 62000 | H30: =G30-F30 -> 48067 | I30: =H30/G30 -> 0.77527419
A31: Full Front — Xpel Ultimate Plus | B31: 27055 | C31: 100000 | D31: =C31-B31 -> 72945 | E31: =D31/C31 -> 0.72945 | F31: 27055 | G31: 125000 | H31: =G31-F31 -> 97945 | I31: =H31/G31 -> 0.78356
A32: Full Front — 3M Scotchgard (Glossy) | B32: 29313 | C32: 140000 | D32: =C32-B32 -> 110687 | E32: =D32/C32 -> 0.79062143 | F32: 29313 | G32: 170000 | H32: =G32-F32 -> 140687 | I32: =H32/G32 -> 0.82757059
A33: Full Front — 3M Scotchgard (Matte) | B33: 30366 | C33: 150000 | D33: =C33-B33 -> 119634 | E33: =D33/C33 -> 0.79756 | F33: 30366 | G33: 180000 | H33: =G33-F33 -> 149634 | I33: =H33/G33 -> 0.8313
A34: Full Body — Xpel Ultimate Plus | B34: 85711 | C34: 180000 | D34: =C34-B34 -> 94289 | E34: =D34/C34 -> 0.52382778 | F34: 85711 | G34: 220000 | H34: =G34-F34 -> 134289 | I34: =H34/G34 -> 0.61040455
A35: Full Body — 3M Scotchgard (Glossy) | B35: 92311 | C35: 350000 | D35: =C35-B35 -> 257689 | E35: =D35/C35 -> 0.73625429 | F35: 92311 | G35: 420000 | H35: =G35-F35 -> 327689 | I35: =H35/G35 -> 0.7802119
A36: Full Body — 3M Scotchgard (Matte) | B36: 95389 | C36: 370000 | D36: =C36-B36 -> 274611 | E36: =D36/C36 -> 0.74219189 | F36: 95389 | G36: 440000 | H36: =G36-F36 -> 344611 | I36: =H36/G36 -> 0.78320682
A38: WINDOW TINT
A39: Package / Film | B39: Cost Sedan | C39: Final Price Sedan | D39: Profit Sedan | E39: Margin Sedan | F39: Cost SUV | G39: Final Price SUV | H39: Profit SUV | I39: Margin SUV
A40: Full Car — Chinese (Value) | B40: 8091 | C40: 25000 | D40: =C40-B40 -> 16909 | E40: =D40/C40 -> 0.67636 | F40: 8091 | G40: 27500 | H40: =G40-F40 -> 19409 | I40: =H40/G40 -> 0.70578182
A41: Full Car — Llumar CTX (Mid) | B41: 8911 | C41: 55000 | D41: =C41-B41 -> 46089 | E41: =D41/C41 -> 0.83798182 | F41: 8911 | G41: 59000 | H41: =G41-F41 -> 50089 | I41: =H41/G41 -> 0.8489661
A42: Full Car — IRX / 3M Crystalline (Top) | B42: 8911 | C42: 72000 | D42: =C42-B42 -> 63089 | E42: =D42/C42 -> 0.87623611 | F42: 8911 | G42: 77000 | H42: =G42-F42 -> 68089 | I42: =H42/G42 -> 0.88427273
A43: Sides + Rear — Chinese (Value) | B43: 5185 | C43: 18000 | D43: =C43-B43 -> 12815 | E43: =D43/C43 -> 0.71194444 | F43: 5185 | G43: 20000 | H43: =G43-F43 -> 14815 | I43: =H43/G43 -> 0.74075
A44: Sides + Rear — Llumar CTX (Mid) | B44: 5753 | C44: 39000 | D44: =C44-B44 -> 33247 | E44: =D44/C44 -> 0.85248718 | F44: 5753 | G44: 42000 | H44: =G44-F44 -> 36247 | I44: =H44/G44 -> 0.86302381
A45: Sides + Rear — IRX / 3M Crystalline (Top) | B45: 5753 | C45: 51500 | D45: =C45-B45 -> 45747 | E45: =D45/C45 -> 0.88829126 | F45: 5753 | G45: 55000 | H45: =G45-F45 -> 49247 | I45: =H45/G45 -> 0.8954
...

Sheet À La Carte (By Problem)
A1: DETAILHAUS — À LA CARTE (BY PROBLEM) MENU
A2: Individual fixes customers can pick in the site's “By problem” mode. Prices [Sedan, SUV] match the live site and are benchmarked to the package rates. Fixes that map 1:1 to a costed package/add-on carry that item's landed cost, profit and margin (black formulas). Partial-scope fixes are sub-components of a larger package and are not separately costed — their retail is benchmarked to the package rate.
A4: Fix (customer-facing) | B4: Cost Sedan | C4: Final Price Sedan | D4: Profit Sedan | E4: Margin Sedan | F4: Cost SUV | G4: Final Price SUV | H4: Profit SUV | I4: Margin SUV | J4: Basis / maps to
A5: EXTERIOR
A6: Exterior wash & shine | B6: 700.11 | C6: 5000 | D6: =C6-B6 -> 4299.89 | E6: =D6/C6 -> 0.859978 | F6: 910.14 | G6: 7000 | H6: =G6-F6 -> 6089.86 | I6: =H6/G6 -> 0.86998 | J6: Maps to bronze — Express Wash & Shine
A7: Heavy decontamination wash | C7: 8000 | G7: 10000 | J7: Between Bronze & Silver — benchmarked sub-scope
A8: 3-step paint correction | B8: 749.58 | C8: 22000 | D8: =C8-B8 -> 21250.42 | E8: =D8/C8 -> 0.96592818 | F8: 974.45 | G8: 28000 | H8: =G8-F8 -> 27025.55 | I8: =H8/G8 -> 0.96519821 | J8: Maps to paint correction (3-step polish) add-on
A9: Clay-bar decontamination | C9: 6000 | G9: 8000 | J9: Sub-scope of Gold / Paint Correction — benchmarked
A10: Trim restoration & coating | C10: 6000 | G10: 8000 | J10: Sub-scope of Gold — benchmarked
A11: Headlight restoration | C11: 5000 | G11: 6000 | J11: Sub-scope of Silver / Gold — benchmarked
A12: Wheel & arch deep clean | C12: 3500 | G12: 4500 | J12: Sub-scope of Bronze — benchmarked
A13: Glass polish & coating | B13: 3473.68 | C13: 10000 | D13: =C13-B13 -> 6526.32 | E13: =D13/C13 -> 0.652632 | F13: 4515.78 | G13: 12000 | H13: =G13-F13 -> 7484.22 | I13: =H13/G13 -> 0.623685 | J13: Maps to glass coating (standalone) add-on
A14: INTERIOR
A15: Interior vacuum & wipe-down | C15: 4000 | G15: 5000 | J15: Sub-scope of Bronze — benchmarked
A16: Shampoo & extraction | C16: 12000 | G16: 15000 | J16: Sub-scope of Silver — benchmarked
A17: Interior dressing & restoration | C17: 4000 | G17: 5000 | J17: Sub-scope of Bronze / Silver — benchmarked
A18: Leather deep clean & condition | C18: 6000 | G18: 7500 | J18: Sub-scope of Silver — benchmarked
A19: A/C deep clean & deodorise | B19: 1737.97 | C19: 3500 | D19: =C19-B19 -> 1762.03 | E19: =D19/C19 -> 0.50343714 | F19: 2259.36 | G19: 4500 | H19: =G19-F19 -> 2240.64 | I19: =H19/G19 -> 0.49792 | J19: Maps to a/c deep clean & decontamination add-on
A20: Pet-hair removal | C20: 3000 | G20: 4000 | J20: Interior sub-scope — benchmarked
A21: EXTRAS
A22: Engine bay clean & dress | C22: 4000 | G22: 5000 | J22: Sub-scope of Silver — benchmarked
A23: New Car Detailing (salt decon) | B23: 4467.47 | C23: 45000 | D23: =C23-B23 -> 40532.53 | E23: =D23/C23 -> 0.90072289 | F23: 5807.71 | G23: 55000 | H23: =G23-F23 -> 49192.29 | I23: =H23/G23 -> 0.89440527 | J23: Maps to new car detailing

Sheet Equipment
A1: EQUIPMENT & DURABLE ASSETS (one-time capital cost — NOT consumed per job, EM20260613)
A2: These items are one-time purchases (capital investment), not per-job consumables. They are NOT included in any package cost above. Landed cost = EXW x uplift factor (from Assumptions tab).
A4: Model | B4: Item | C4: Pack/Unit | D4: EXW Unit Price (USD) | E4: Landed Cost (USD) | F4: Landed Cost (KES)
A5: SG-100 | B5: 14 Hexagon Studio Lights — Workshop lighting | C5: 1 KIT | D5: 110 | E5: =D5*Assumptions!$B$21 -> 151.43374 | F5: =E5*Assumptions!$B$5 -> 20443.555
A6: T-120 | B6: Tornado Engine Long Tube Cleaning Gun — Engine bay cleaning gun | C6: 1 unit | D6: 27 | E6: =D6*Assumptions!$B$21 -> 37.170099 | F6: =E6*Assumptions!$B$5 -> 5017.9634
A7: T-724 | B7: DA Electrical Polisher 5 Inch — Dual-action polisher | C7: 1 unit | D7: 69 | E7: =D7*Assumptions!$B$21 -> 94.990254 | F7: =E7*Assumptions!$B$5 -> 12823.684
A8: T-624 | B8: Soft Wool Car Wash Gloves 1 Pair — Wash mitt | C8: 1 pair | D8: 1.79 | E8: =D8*Assumptions!$B$21 -> 2.4642399 | F8: =E8*Assumptions!$B$5 -> 332.67239
A9: T-810 | B9: Chenille Car Wash Mitt Gray — Wash mitt | C9: 1 unit | D9: 1.1 | E9: =D9*Assumptions!$B$21 -> 1.5143374 | F9: =E9*Assumptions!$B$5 -> 204.43555
A10: T-618 | B10: Car Wash Sponge — Wash sponge | C10: 1 unit | D10: 0.7 | E10: =D10*Assumptions!$B$21 -> 0.96366924 | F10: =E10*Assumptions!$B$5 -> 130.09535
A11: T-629 | B11: Yellow Tire Brush — Tire brush | C11: 1 unit | D11: 1 | E11: =D11*Assumptions!$B$21 -> 1.3766703 | F11: =E11*Assumptions!$B$5 -> 185.8505
A12: T-752 | B12: SRB Red Wheel Cleaning Brush Large — Wheel brush | C12: 1 unit | D12: 2.5 | E12: =D12*Assumptions!$B$21 -> 3.4416759 | F12: =E12*Assumptions!$B$5 -> 464.62624
A13: T-628 | B13: Circle Wheel Hub Brush — Wheel hub brush | C13: 1 unit | D13: 0.7 | E13: =D13*Assumptions!$B$21 -> 0.96366924 | F13: =E13*Assumptions!$B$5 -> 130.09535
A14: T-316 | B14: Car Wash Foam Lance/Cannon (1L) — Foam cannon | C14: 1 unit | D14: 12 | E14: =D14*Assumptions!$B$21 -> 16.520044 | F14: =E14*Assumptions!$B$5 -> 2230.206
A15: T-10 | B15: Hand Pump Foam Sprayer White (2L) — Hand pump foam sprayer | C15: 1 unit | D15: 3.1 | E15: =D15*Assumptions!$B$21 -> 4.2676781 | F15: =E15*Assumptions!$B$5 -> 576.13654
A16: SG-326 | B16: Handheld Inspection Light — Inspection light | C16: 1 unit | D16: 9.2 | E16: =D16*Assumptions!$B$21 -> 12.665367 | F16: =E16*Assumptions!$B$5 -> 1709.8246
... A28: MINI-PAD | B28: Mini Pad Set — Mini polisher pad set | C28: 1 set | D28: 7.6 | E28: =D28*Assumptions!$B$21 -> 10.462695 | F28: =E28*Assumptions!$B$5 -> 1412.4638
A29: TOTAL EQUIPMENT (one-time) | D29: =SUM(D5:D28) -> 608.59 | E29: =SUM(E5:E28) -> 837.82781 | F29: =SUM(F5:F28) -> 113106.75

Sheet Product Costs
A1: LANDED UNIT COSTS — CONSUMABLES (from SRB Invoice EM20260613)
A2: Landed unit cost = EXW unit price (USD) x uplift factor (Assumptions tab). Pack size shows units per carton/pack/dilution for per-use cost calc. Equipment/durable tools are listed separately on the 'Equipment' tab and are NOT consumed per job.
A4: Model | B4: Product | C4: Pack/Unit Size | D4: EXW Unit Price (USD/PC) | E4: Landed Unit Cost (USD) | F4: Landed Unit Cost (KES) | G4: Est. uses per pack | H4: Cost per use (USD) | I4: Cost per use (KES)
A5: D15 | B5: Touchless Pink Foam Pre Wash (20L, 1:300 hand pump foam) — Foam pre-wash, used in every wash/detail job | C5: 20L | D5: 20 | E5: =D5*Assumptions!$B$21 -> 27.533407 | F5: =E5*Assumptions!$B$5 -> 3717.0099 | G5: 333 | H5: =E5/G5 -> 0.082682904 | I5: =F5/G5 -> 11.162192
A6: C55 | B6: SRB Engine Cleaning Agent (20L, diluted 1:3-5, ~300ml mix/job) — Engine bay degreasing, used in Full Detail and above | C6: 20L | D6: 40 | E6: =D6*Assumptions!$B$21 -> 55.066814 | F6: =E6*Assumptions!$B$5 -> 7434.0199 | G6: 333 | H6: =E6/G6 -> 0.16536581 | I6: =F6/G6 -> 22.324384
A7: R1 | B7: Graphene Pre Wash (20L, 1:15 foam cannon avg) — Premium pre-wash for coating/decon jobs | C7: 20L | D7: 55 | E7: =D7*Assumptions!$B$21 -> 75.716869 | F7: =E7*Assumptions!$B$5 -> 10221.777 | G7: 154 | H7: =E7/G7 -> 0.49166798 | I7: =F7/G7 -> 66.375178
A8: R2 | B8: Graphene Car Shampoo (20L, 1:15 foam cannon avg) — Premium shampoo wash | C8: 20L | D8: 55 | E8: =D8*Assumptions!$B$21 -> 75.716869 | F8: =E8*Assumptions!$B$5 -> 10221.777 | G8: 154 | H8: =E8/G8 -> 0.49166798 | I8: =F8/G8 -> 66.375178
A9: S32 | B9: High Foam Shampoo (20L, 1:10 foam cannon) — Standard wash shampoo | C9: 20L | D9: 45 | E9: =D9*Assumptions!$B$21 -> 61.950166 | F9: =E9*Assumptions!$B$5 -> 8363.2724 | G9: 100 | H9: =E9/G9 -> 0.61950166 | I9: =F9/G9 -> 83.632724
A10: S7 | B10: Iron Remover (4L, ~150ml/wheel set sedan) — Decon step, removes brake dust | C10: 4L | D10: 18 | E10: =D10*Assumptions!$B$21 -> 24.780066 | F10: =E10*Assumptions!$B$5 -> 3345.3089 | G10: 27 | H10: =E10/G10 -> 0.91778023 | I10: =F10/G10 -> 123.90033
A11: S8 | B11: Tar & Glue Remover (1L, ~20ml/job spot use) — Spot removal of tar/glue/sap | C11: 1L | D11: 5.8 | E11: =D11*Assumptions!$B$21 -> 7.984688 | F11: =E11*Assumptions!$B$5 -> 1077.9329 | G11: 50 | H11: =E11/G11 -> 0.15969376 | I11: =F11/G11 -> 21.558658
A12: W22 | B12: SRB Scratch Wax (250ml, ~10ml/job spot use) — Light scratch touch-up | C12: 250ml | D12: 2.5 | E12: =D12*Assumptions!$B$21 -> 3.4416759 | F12: =E12*Assumptions!$B$5 -> 464.62624 | G12: 25 | H12: =E12/G12 -> 0.13766703 | I12: =F12/G12 -> 18.58505
A13: R6 | B13: Graphene Detail Spray (20L, ~60ml/job) — Quick detailer top-up spray | C13: 20L | D13: 115 | E13: =D13*Assumptions!$B$21 -> 158.31709 | F13: =E13*Assumptions!$B$5 -> 21372.807 | G13: 333 | H13: =E13/G13 -> 0.4754267 | I13: =F13/G13 -> 64.182604
A14: S11 | B14: Ceramic Quick Detailer (20L, ~60ml/job) — Quick detailer, ceramic-boosting | C14: 20L | D14: 98 | E14: =D14*Assumptions!$B$21 -> 134.91369 | F14: =E14*Assumptions!$B$5 -> 18213.349 | G14: 333 | H14: =E14/G14 -> 0.40514623 | I14: =F14/G14 -> 54.694741
A15: SRB011 | B15: SRB Graphene Coating 10H (1L kit, 1 vehicle) — Graphene 10H coating kit | C15: 1L kit | D15: 115 | E15: =D15*Assumptions!$B$21 -> 158.31709 | F15: =E15*Assumptions!$B$5 -> 21372.807 | G15: 1 | H15: =E15/G15 -> 158.31709 | I15: =F15/G15 -> 21372.807
A16: R13 | B16: SRB Graphene Coating 20H (1L kit, 1 vehicle) — Graphene 20H flagship coating kit | C16: 1L kit | D16: 275 | E16: =D16*Assumptions!$B$21 -> 378.58435 | F16: =E16*Assumptions!$B$5 -> 51108.887 | G16: 1 | H16: =E16/G16 -> 378.58435 | I16: =F16/G16 -> 51108.887
... A71: C-373 | B71: SRB Glass Reconditioning Agent (1Gal, ~100ml/job) — Removes water spots, acid rain marks and traffic film from glass | C71: 1Gal | D71: 20 | E71: =D71*Assumptions!$B$21 -> 27.533407 | F71: =E71*Assumptions!$B$5 -> 3717.0099 | G71: 38 | H71: =E71/G71 -> 0.72456334 | I71: =F71/G71 -> 97.816051

Sheet Package Costing
A1: DETAILHAUS — FINAL PACKAGE COSTING (Sedan vs SUV) — 14 Jun 2026
A2: Cost = sum of (landed cost per use × quantity) for consumables used in the package. SUV quantities are Sedan × 1.30. Product cost, labour and TOTAL COST are unchanged from the original cost model — only the pricing layer is new. FINAL RETAIL PRICE (blue) reflects the competitor-benchmarked retail prices set in this pricing review; PROFIT = FINAL RETAIL PRICE − TOTAL COST; MARGIN % = PROFIT / FINAL RETAIL PRICE.
A4: BRONZE — Express Wash & Shine | B4: Tier: Entry
A5: Includes: | B5: Our quick, affordable entry detail — everything you'd get at a good local carwash, but done properly with a few extras most carwashes skip. Includes: • Full foam pre-wash and hand wash • Iron removal — dissolves brake dust baked onto your wheels and lower paint (the value-add a normal carwash won't do) • Wheel cleaning and tire shine • Plastic trim cleaning • Streak-free glass cleaning, inside and out • Full interior vacuum • Dashboard and interior trim protection • Hyper dressing — a fresh, non-greasy protective finish on interior plastics and rubber Great for a regular clean-up that leaves the car looking sharp. • Finishing shine: Ceramic Quick Detailer top-up spray for a protective glossy finish
A6: Item / Component | B6: Qty (Sedan) | C6: Qty (SUV) | D6: Unit Cost (USD) | E6: Sedan Cost (USD) | F6: SUV Cost (USD) | G6: Sedan Cost (KES) | H6: SUV Cost (KES)
A7: D15 — see Product Costs tab | B7: 1 | C7: =B7*1.3 -> 1.3 | D7: ='Product Costs'!H5 -> 0.082682904 | E7: =B7*D7 -> 0.082682904 | F7: =C7*D7 -> 0.10748778 | G7: =E7*Assumptions!$B$5 -> 11.162192 | H7: =F7*Assumptions!$B$5 -> 14.51085
A8: S32 — see Product Costs tab | B8: 1 | C8: =B8*1.3 -> 1.3 | D8: ='Product Costs'!H9 -> 0.61950166 | E8: =B8*D8 -> 0.61950166 | F8: =C8*D8 -> 0.80535215 | G8: =E8*Assumptions!$B$5 -> 83.632724 | H8: =F8*Assumptions!$B$5 -> 108.72254
A9: S7 — see Product Costs tab | B9: 1 | C9: =B9*1.3 -> 1.3 | D9: ='Product Costs'!H10 -> 0.91778023 | E9: =B9*D9 -> 0.91778023 | F9: =C9*D9 -> 1.1931143 | G9: =E9*Assumptions!$B$5 -> 123.90033 | H9: =F9*Assumptions!$B$5 -> 161.07043
A10: C71 — see Product Costs tab | B10: 1 | C10: =B10*1.3 -> 1.3 | D10: ='Product Costs'!H20 -> 0.20650055 | E10: =B10*D10 -> 0.20650055 | F10: =C10*D10 -> 0.26845072 | G10: =E10*Assumptions!$B$5 -> 27.877575 | H10: =F10*Assumptions!$B$5 -> 36.240847
A11: S18 — see Product Costs tab | B11: 1 | C11: =B11*1.3 -> 1.3 | D11: ='Product Costs'!H19 -> 0.28910077 | E11: =B11*D11 -> 0.28910077 | F11: =C11*D11 -> 0.37583101 | G11: =E11*Assumptions!$B$5 -> 39.028604 | H11: =F11*Assumptions!$B$5 -> 50.737186
A12: R4 — see Product Costs tab | B12: 1 | C12: =B12*1.3 -> 1.3 | D12: ='Product Costs'!H18 -> 0.68833517 | E12: =B12*D12 -> 0.68833517 | F12: =C12*D12 -> 0.89483573 | G12: =E12*Assumptions!$B$5 -> 92.925249 | H12: =F12*Assumptions!$B$5 -> 120.80282
A13: S9 — see Product Costs tab | B13: 1 | C13: =B13*1.3 -> 1.3 | D13: ='Product Costs'!H36 -> 0.3854677 | E13: =B13*D13 -> 0.3854677 | F13: =C13*D13 -> 0.50110801 | G13: =E13*Assumptions!$B$5 -> 52.038139 | H13: =F13*Assumptions!$B$5 -> 67.649581
A14: C06 — see Product Costs tab | B14: 1 | C14: =B14*1.3 -> 1.3 | D14: ='Product Costs'!H24 -> 0.71586858 | E14: =B14*D14 -> 0.71586858 | F14: =C14*D14 -> 0.93062916 | G14: =E14*Assumptions!$B$5 -> 96.642259 | H14: =F14*Assumptions!$B$5 -> 125.63494
A15: C65 — see Product Costs tab | B15: 0.5 | C15: =B15*1.3 -> 0.65 | D15: ='Product Costs'!H22 -> 0.31349919 | E15: =B15*D15 -> 0.15674959 | F15: =C15*D15 -> 0.20377447 | G15: =E15*Assumptions!$B$5 -> 21.161195 | H15: =F15*Assumptions!$B$5 -> 27.509554
A16: T-65 — see Product Costs tab | B16: 0.4 | C16: =B16*1.3 -> 0.52 | D16: ='Product Costs'!H49 -> 0.027533407 | E16: =B16*D16 -> 0.011013363 | F16: =C16*D16 -> 0.014317372 | G16: =E16*Assumptions!$B$5 -> 1.486804 | H16: =F16*Assumptions!$B$5 -> 1.9328452
A17: T-353 — see Product Costs tab | B17: 0.2 | C17: =B17*1.3 -> 0.26 | D17: ='Product Costs'!H50 -> 0.019273385 | E17: =B17*D17 -> 0.003854677 | F17: =C17*D17 -> 0.0050110801 | G17: =E17*Assumptions!$B$5 -> 0.52038139 | H17: =F17*Assumptions!$B$5 -> 0.67649581
A18: T-661 — see Product Costs tab | B18: 0.2 | C18: =B18*1.3 -> 0.26 | D18: ='Product Costs'!H47 -> 0.04130011 | E18: =B18*D18 -> 0.0082600221 | F18: =C18*D18 -> 0.010738029 | G18: =E18*Assumptions!$B$5 -> 1.115103 | H18: =F18*Assumptions!$B$5 -> 1.4496339
A19: T-351 — see Product Costs tab | B19: 0.2 | C19: =B19*1.3 -> 0.26 | D19: ='Product Costs'!H48 -> 0.068833517 | E19: =B19*D19 -> 0.013766703 | F19: =C19*D19 -> 0.017896715 | G19: =E19*Assumptions!$B$5 -> 1.858505 | H19: =F19*Assumptions!$B$5 -> 2.4160565
A20: T-535 — see Product Costs tab | B20: 0.3 | C20: =B20*1.3 -> 0.39 | D20: ='Product Costs'!H66 -> 0.018355605 | E20: =B20*D20 -> 0.0055066814 | F20: =C20*D20 -> 0.0071586858 | G20: =E20*Assumptions!$B$5 -> 0.74340199 | H20: =F20*Assumptions!$B$5 -> 0.96642259
A21: S11 — see Product Costs tab | B21: 1 | C21: =B21*1.3 -> 1.3 | D21: ='Product Costs'!H14 -> 0.40514623 | E21: =B21*D21 -> 0.40514623 | F21: =C21*D21 -> 0.5266901 | G21: =E21*Assumptions!$B$5 -> 54.694741 | H21: =F21*Assumptions!$B$5 -> 71.103163
A22: Product cost subtotal | E22: =SUM(E7:E21) -> 4.5095348 | F22: =SUM(F7:F21) -> 5.8623953 | G22: =E22*Assumptions!$B$5 -> 608.7872 | H22: =F22*Assumptions!$B$5 -> 791.42337
A23: Labour add-on (15% of product cost — standard rate) | E23: =E22*Assumptions!$B$9 -> 0.67643023 | F23: =F22*Assumptions!$B$9 -> 0.87935929 | G23: =E23*Assumptions!$B$5 -> 91.318081 | H23: =F23*Assumptions!$B$5 -> 118.7135
A24: TOTAL COST (product + labour) | E24: =E22+E23 -> 5.1859651 | F24: =F22+F23 -> 6.7417546 | G24: =E24*Assumptions!$B$5 -> 700.10528 | H24: =F24*Assumptions!$B$5 -> 910.13687
A25: FINAL RETAIL PRICE (Sedan / SUV, KES) | E25: =G25/Assumptions!$B$5 -> 37.037037 | F25: =H25/Assumptions!$B$5 -> 51.851852 | G25: 5000 | H25: 7000
A26: PROFIT (Final Price − Total Cost) | E26: =E25-E24 -> 31.851072 | F26: =F25-F24 -> 45.110097 | G26: =G25-G24 -> 4299.8947 | H26: =H25-H24 -> 6089.8631
A27: MARGIN % (Profit / Final Price) | G27: =G26/G25 -> 0.85997894 | H27: =H26/H25 -> 0.86998045
A29: SILVER — Household Detail (Recommended) | B29: Tier: Standard
A30: Includes: | B30: Our most popular package — the recommended choice for the family car. Everything in Bronze, PLUS a proper interior and exterior refresh: • Everything in Bronze (wash, iron removal, wheels, tires, glass, vacuum, dashboard, hyper dressing) • Deep interior clean and steam cleaning of seats, carpets and door panels • Fabric and leather protective coating (seats, mats, convertible tops) to repel water and stains • Engine bay wash and degrease, finished with a protective dressing • Watermark and water-spot removal on glass — acid rain marks, traffic film and hard-water spots polished off the windscreen and windows • Headlight restoration — cloudy or yellow headlights sanded, restored and ceramic-coated for lasting clarity The complete household detail that keeps your car fresh inside and out. • Finishing shine: Ceramic Quick Detailer top-up spray for a protective glossy finish • Roof/ceiling (headliner) cleaning — wiped and treated for a fresh, stain-free interior top • Seatbelt cleaning — webbing and buckles cleaned, removing grime that builds up from regular use
A31: Item / Component | B31: Qty (Sedan) | C31: Qty (SUV) | D31: Unit Cost (USD) | E31: Sedan Cost (USD) | F31: SUV Cost (USD) | G31: Sedan Cost (KES) | H31: SUV Cost (KES)
A32: D15 — see Product Costs tab | B32: 1 | C32: =B32*1.3 -> 1.3 | D32: ='Product Costs'!H5 -> 0.082682904 | E32: =B32*D32 -> 0.082682904 | F32: =C32*D32 -> 0.10748778 | G32: =E32*Assumptions!$B$5 -> 11.162192 | H32: =F32*Assumptions!$B$5 -> 14.51085
A33: S32 — see Product Costs tab | B33: 1 | C33: =B33*1.3 -> 1.3 | D33: ='Product Costs'!H9 -> 0.61950166 | E33: =B33*D33 -> 0.61950166 | F33: =C33*D33 -> 0.80535215 | G33: =E33*Assumptions!$B$5 -> 83.632724 | H33: =F33*Assumptions!$B$5 -> 108.72254
A34: S7 — see Product Costs tab | B34: 1 | C34: =B34*1.3 -> 1.3 | D34: ='Product Costs'!H10 -> 0.91778023 | E34: =B34*D34 -> 0.91778023 | F34: =C34*D34 -> 1.1931143 | G34: =E34*Assumptions!$B$5 -> 123.90033 | H34: =F34*Assumptions!$B$5 -> 161.07043
A35: C71 — see Product Costs tab | B35: 1 | C35: =B35*1.3 -> 1.3 | D35: ='Product Costs'!H20 -> 0.20650055 | E35: =B35*D35 -> 0.20650055 | F35: =C35*D35 -> 0.26845072 | G35: =E35*Assumptions!$B$5 -> 27.877575 | H35: =F35*Assumptions!$B$5 -> 36.240847
A36: S18 — see Product Costs tab | B36: 1 | C36: =B36*1.3 -> 1.3 | D36: ='Product Costs'!H19 -> 0.28910077 | E36: =B36*D36 -> 0.28910077 | F36: =C36*D36 -> 0.37583101 | G36: =E36*Assumptions!$B$5 -> 39.028604 | H36: =F36*Assumptions!$B$5 -> 50.737186
A37: R4 — see Product Costs tab | B37: 1 | C37: =B37*1.3 -> 1.3 | D37: ='Product Costs'!H18 -> 0.68833517 | E37: =B37*D37 -> 0.68833517 | F37: =C37*D37 -> 0.89483573 | G37: =E37*Assumptions!$B$5 -> 92.925249 | H37: =F37*Assumptions!$B$5 -> 120.80282
A38: S9 — see Product Costs tab | B38: 1 | C38: =B38*1.3 -> 1.3 | D38: ='Product Costs'!H36 -> 0.3854677 | E38: =B38*D38 -> 0.3854677 | F38: =C38*D38 -> 0.50110801 | G38: =E38*Assumptions!$B$5 -> 52.038139 | H38: =F38*Assumptions!$B$5 -> 67.649581
A39: C06 — see Product Costs tab | B39: 1 | C39: =B39*1.3 -> 1.3 | D39: ='Product Costs'!H24 -> 0.71586858 | E39: =B39*D39 -> 0.71586858 | F39: =C39*D39 -> 0.93062916 | G39: =E39*Assumptions!$B$5 -> 96.642259 | H39: =F39*Assumptions!$B$5 -> 125.63494
A40: C65 — see Product Costs tab | B40: 0.5 | C40: =B40*1.3 -> 0.65 | D40: ='Product Costs'!H22 -> 0.31349919 | E40: =B40*D40 -> 0.15674959 | F40: =C40*D40 -> 0.20377447 | G40: =E40*Assumptions!$B$5 -> 21.161195 | H40: =F40*Assumptions!$B$5 -> 27.509554
A41: T-65 — see Product Costs tab | B41: 0.6 | C41: =B41*1.3 -> 0.78 | D41: ='Product Costs'!H49 -> 0.027533407 | E41: =B41*D41 -> 0.016520044 | F41: =C41*D41 -> 0.021476057 | G41: =E41*Assumptions!$B$5 -> 2.230206 | H41: =F41*Assumptions!$B$5 -> 2.8992678
A42: T-353 — see Product Costs tab | B42: 0.2 | C42: =B42*1.3 -> 0.26 | D42: ='Product Costs'!H50 -> 0.019273385 | E42: =B42*D42 -> 0.003854677 | F42: =C42*D42 -> 0.0050110801 | G42: =E42*Assumptions!$B$5 -> 0.52038139 | H42: =F42*Assumptions!$B$5 -> 0.67649581
...
